{
    "registryname": "electroplater",
    "localizedname": "Electroplater",
    "color" : "727472",
    "parts": [
        {
            "x": -1,
            "y": 2,
            "z": 3,
            "elements": [
                "gregtech:metal_casing@0"
            ]
        },
        {
            "x": 1,
            "y": 2,
            "z": 1,
            "elements": [
                "gregtech:metal_casing@0"
            ]
        },
        {
            "x": 0,
            "y": 2,
            "z": 2,
            "elements": [
                "gregtech:metal_casing@0"
            ]
        },
        {
            "x": -1,
            "y": 0,
            "z": 1,
            "elements": [
                "gregtech:metal_casing@0"
            ]
        },
        {
            "x": 0,
            "y": 2,
            "z": 3,
            "elements": [
                "gregtech:metal_casing@0"
            ]
        },
        {
            "x": 1,
            "y": 2,
            "z": 2,
            "elements": [
                "gregtech:metal_casing@0"
            ]
        },
        {
            "x": -1,
            "y": 0,
            "z": 2,
            "elements": [
                "gregtech:metal_casing@0"
            ]
        },
        {
            "x": 0,
            "y": 0,
            "z": 1,
            "elements": [
                "gregtech:metal_casing@0"
            ]
        },
        {
            "x": -2,
            "y": 0,
            "z": 3,
            "elements": [
                "modularmachinery:blockoutputbus"
            ]
        },
        {
            "x": 1,
            "y": 2,
            "z": 3,
            "elements": [
                "gregtech:metal_casing@0"
            ]
        },
        {
            "x": 0,
            "y": 0,
            "z": 2,
            "elements": [
                "gregtech:metal_casing@0"
            ]
        },
        {
            "x": -1,
            "y": 0,
            "z": 3,
            "elements": [
                "gregtech:metal_casing@0"
            ]
        },
        {
            "x": 1,
            "y": 0,
            "z": 1,
            "elements": [
                "gregtech:metal_casing@0"
            ]
        },
        {
            "x": 1,
            "y": 0,
            "z": 2,
            "elements": [
                "gregtech:metal_casing@0"
            ]
        },
        {
            "x": 0,
            "y": 0,
            "z": 3,
            "elements": [
                "gregtech:metal_casing@0"
            ]
        },
        {
            "x": 2,
            "y": 0,
            "z": 1,
            "elements": [
                "modularmachinery:blockfluidinputhatch"
            ]
        },
        {
            "x": 1,
            "y": 0,
            "z": 3,
            "elements": [
                "gregtech:metal_casing@0"
            ]
        },
        {
            "x": 2,
            "y": 0,
            "z": 3,
            "elements": [
                "modularmachinery:blockinputbus"
            ]
        },
        {
            "x": -2,
            "y": 1,
            "z": 0,
            "elements": [
                "gregtech:metal_casing@0"
            ]
        },
        {
            "x": -2,
            "y": 1,
            "z": 1,
            "elements": [
                "gregtech:metal_casing@0"
            ]
        },
        {
            "x": -1,
            "y": 1,
            "z": 0,
            "elements": [
                "gregtech:metal_casing@0"
            ]
        },
        {
            "x": -1,
            "y": 1,
            "z": 1,
            "elements": [
                "gregtech:compressed_0@15"
            ]
        },
        {
            "x": -2,
            "y": 1,
            "z": 2,
            "elements": [
                "gregtech:metal_casing@0"
            ]
        },
        {
            "x": 0,
            "y": 1,
            "z": 0,
            "elements": [
                "gregtech:metal_casing@0"
            ]
        },
        {
            "x": 0,
            "y": 1,
            "z": 1,
            "elements": [
                "gregtech:compressed_0@15"
            ]
        },
        {
            "x": -1,
            "y": 1,
            "z": 2,
            "elements": [
                "gregtech:compressed_0@15"
            ]
        },
        {
            "x": -2,
            "y": 1,
            "z": 3,
            "elements": [
                "gregtech:metal_casing@0"
            ]
        },
        {
            "x": 1,
            "y": 1,
            "z": 0,
            "elements": [
                "gregtech:metal_casing@0"
            ]
        },
        {
            "x": 0,
            "y": 1,
            "z": 2,
            "elements": [
                "minecraft:water@0"
            ]
        },
        {
            "x": 1,
            "y": 1,
            "z": 1,
            "elements": [
                "gregtech:compressed_0@15"
            ]
        },
        {
            "x": -1,
            "y": 1,
            "z": 3,
            "elements": [
                "gregtech:compressed_0@15"
            ]
        },
        {
            "x": -2,
            "y": 1,
            "z": 4,
            "elements": [
                "gregtech:metal_casing@0"
            ]
        },
        {
            "x": 2,
            "y": 1,
            "z": 0,
            "elements": [
                "gregtech:metal_casing@0"
            ]
        },
        {
            "x": 0,
            "y": 1,
            "z": 3,
            "elements": [
                "gregtech:compressed_0@15"
            ]
        },
        {
            "x": 1,
            "y": 1,
            "z": 2,
            "elements": [
                "gregtech:compressed_0@15"
            ]
        },
        {
            "x": 2,
            "y": 1,
            "z": 1,
            "elements": [
                "gregtech:metal_casing@0"
            ]
        },
        {
            "x": -1,
            "y": 1,
            "z": 4,
            "elements": [
                "gregtech:metal_casing@0"
            ]
        },
        {
            "x": 1,
            "y": 1,
            "z": 3,
            "elements": [
                "gregtech:compressed_0@15"
            ]
        },
        {
            "x": 2,
            "y": 1,
            "z": 2,
            "elements": [
                "gregtech:metal_casing@0"
            ]
        },
        {
            "x": 0,
            "y": 1,
            "z": 4,
            "elements": [
                "gregtech:metal_casing@0"
            ]
        },
        {
            "x": 2,
            "y": 1,
            "z": 3,
            "elements": [
                "gregtech:metal_casing@0"
            ]
        },
        {
            "x": 1,
            "y": 1,
            "z": 4,
            "elements": [
                "gregtech:metal_casing@0"
            ]
        },
        {
            "x": 2,
            "y": 1,
            "z": 4,
            "elements": [
                "gregtech:metal_casing@0"
            ]
        },
        {
            "x": -1,
            "y": 2,
            "z": 1,
            "elements": [
                "gregtech:metal_casing@0"
            ]
        },
        {
            "x": -1,
            "y": 2,
            "z": 2,
            "elements": [
                "gregtech:metal_casing@0"
            ]
        },
        {
            "x": 0,
            "y": 2,
            "z": 1,
            "elements": [
                "gregtech:metal_casing@0"
            ]
        },
        {
            "x": -2,
            "y": 0,
            "z": 1,
            "elements": [
                "modularmachinery:blockenergyinputhatch"
            ]
        }
    ]}